<?xml version="1.0"?>
<robot xmlns:xacro="http://www.ros.org/wiki/xacro" name="example">
  <xacro:arg name="gpu" default="false"/>
  <xacro:property name="gpu" value="$(arg gpu)" />
  <xacro:arg name="organize_cloud" default="false"/>
  <xacro:property name="organize_cloud" value="$(arg organize_cloud)" />

  <!-- Base Footprint -->
  <link name="base_footprint" />

  <!-- Base Link -->
  <joint name="footprint" type="fixed">
    <parent link="base_footprint" />
    <child link="base_link" />
    <origin xyz="0 0 0.05" rpy="0 0 0" />
  </joint>
  <link name="base_link">
    <visual>
      <geometry>
        <box size="0.5 0.5 0.1" />
      </geometry>
    </visual>
    <collision>
      <geometry>
        <box size="0.5 0.5 0.1" />
      </geometry>
    </collision>
    <inertial>
      <origin xyz="0 0 0"/>
      <mass value="10"/>
      <inertia ixx="3.0" ixy="0.0" ixz="0.0"
               iyy="3.0" iyz="0.0"
               izz="3.0" />
    </inertial>
  </link>

  <!-- Left Wheel 1 -->
  <link name="left_wheel_1">
    <visual>
      <geometry>
        <cylinder radius="0.1" length="0.05" />
      </geometry>
    </visual>
    <collision>
      <geometry>
        <cylinder radius="0.1" length="0.05" />
      </geometry>
    </collision>
    <inertial>
      <origin xyz="0 0 0" />
      <mass value="0.5" />
      <inertia ixx="0.01" ixy="0" ixz="0"
               iyy="0.01" iyz="0"
               izz="0.01" />
    </inertial>
  </link>

  <!-- Right Wheel 1 -->
  <link name="right_wheel_1">
    <visual>
      <geometry>
        <cylinder radius="0.1" length="0.05" />
      </geometry>
    </visual>
    <collision>
      <geometry>
        <cylinder radius="0.1" length="0.05" />
      </geometry>
    </collision>
    <inertial>
      <origin xyz="0 0 0" />
      <mass value="0.5" />
      <inertia ixx="0.01" ixy="0" ixz="0"
               iyy="0.01" iyz="0"
               izz="0.01" />
    </inertial>
  </link>

  <!-- Left Wheel Joint 1 -->
  <joint name="left_wheel_joint_1" type="revolute">
    <parent link="base_link" />
    <child link="left_wheel_1" />
    <origin xyz="-0.2 -0.28 -0.05" rpy="1.5708 0 0" />
    <axis xyz="0 0 -1" />
    <limit lower="-3.1416" upper="1000" effort="100" velocity="1.0" />
  </joint>

  <!-- Right Wheel Joint 1 -->
  <joint name="right_wheel_joint_1" type="revolute">
    <parent link="base_link" />
    <child link="right_wheel_1" />
    <origin xyz="-0.2 0.28 -0.05" rpy="1.5708 0 0" />
    <axis xyz="0 0 1" />
    <limit lower="-3.1416" upper="1000" effort="100" velocity="0.1" />
  </joint>
  
  
  
  
  
  
  
  
  <!-- Left Wheel 2 -->
  <link name="left_wheel_2">
    <visual>
      <geometry>
        <cylinder radius="0.1" length="0.05" />
      </geometry>
    </visual>
    <collision>
      <geometry>
        <cylinder radius="0.1" length="0.05" />
      </geometry>
    </collision>
    <inertial>
      <origin xyz="0 0 0" />
      <mass value="0.5" />
      <inertia ixx="0.01" ixy="0" ixz="0"
               iyy="0.01" iyz="0"
               izz="0.01" />
    </inertial>
  </link>

  <!-- Right Wheel 2 -->
  <link name="right_wheel_2">
    <visual>
      <geometry>
        <cylinder radius="0.1" length="0.05" />
      </geometry>
    </visual>
    <collision>
      <geometry>
        <cylinder radius="0.1" length="0.05" />
      </geometry>
    </collision>
    <inertial>
      <origin xyz="0 0 0" />
      <mass value="0.5" />
      <inertia ixx="0.01" ixy="0" ixz="0"
               iyy="0.01" iyz="0"
               izz="0.01" />
    </inertial>
  </link>

  <!-- Left Wheel Joint 2 -->
  <joint name="left_wheel_joint_2" type="revolute">
    <parent link="base_link" />
    <child link="left_wheel_2" />
    <origin xyz="0.2 -0.28 -0.05" rpy="1.5708 0 0" />
    <axis xyz="0 0 -1" />
    <limit lower="-3.1416" upper="1000" effort="100" velocity="1.0" />
  </joint>

  <!-- Right Wheel Joint 2 -->
  <joint name="right_wheel_joint_2" type="revolute">
    <parent link="base_link" />
    <child link="right_wheel_2" />
    <origin xyz="0.2 0.28 -0.05" rpy="1.5708 0 0" />
    <axis xyz="0 0 1" />
    <limit lower="-3.1416" upper="1000" effort="100" velocity="0.1" />
  </joint>
  
  
  
  
  
  
  
  
  

  <xacro:include filename="$(find velodyne_description)/urdf/VLP-16.urdf.xacro"/>
  <xacro:VLP-16 parent="base_link" name="velodyne" topic="/velodyne_points" organize_cloud="${organize_cloud}" hz="10" samples="440" gpu="${gpu}">
    <origin xyz="0 0 0.4" rpy="0 0 0" />
  </xacro:VLP-16>

  <xacro:include filename="$(find velodyne_description)/urdf/HDL-32E.urdf.xacro"/>
  <xacro:HDL-32E parent="base_link" name="velodyne2" topic="/velodyne_points2" organize_cloud="${organize_cloud}" hz="10" samples="220" gpu="${gpu}">
    <origin xyz="0 0 0.6" rpy="0 0 0" />
  </xacro:HDL-32E>

</robot>
